<?xml version="1.0"?>
<robot name="tortoisebot">
  <link name="base_link">
    <visual>
      <geometry>
        <box size=".6 .3 .2"/>
      </geometry>
      <material name="silver">
        <color rgba = ".75 .75 .75 1"/>
      </material>
    </visual>
    <collision>
      <geometry>
        <box size=".6 .3 .2"/>
      </geometry>
    </collision>
    <inertial>
      <mass value = "100"/>
      <inertia ixx="4.0" iyy="8" izz="8" ixy="0" ixz="0" iyz="0"/>
    </inertial>
  </link>

  <link name="front_right_caster">
    <visual>
      <geometry>
        <box size=".1 .1 .1"/>
      </geometry>
      <material name="silver"/>
    </visual>
    <collision>
      <geometry>
        <box size=".1 .1 .1"/>
      </geometry>
    </collision>
    <inertial>
      <mass value = ".10"/>
      <inertia ixx=".00083" iyy=".00083" izz=".00083" ixy="0" ixz="0" iyz="0"/>
    </inertial>
  </link>

  <joint name="front_right_caster_joint" type = "continuous">
    <axis xyz="0 0 1"/>
    <parent link="base_link"/>
    <child link="front_right_caster"/>
    <origin rpy="0 0 0" xyz=".3 .15 -.1"/>
    <dynamics damping="0.01" friction="100"/>
  </joint>

  <link name="front_left_caster">
    <visual>
      <geometry>
        <box size=".1 .1 .1"/>
      </geometry>
      <material name="silver"/>
    </visual>
    <collision>
      <geometry>
        <box size=".1 .1 .1"/>
      </geometry>
    </collision>
    <inertial>
      <mass value = ".10"/>
      <inertia ixx=".00083" iyy=".00083" izz=".00083" ixy="0" ixz="0" iyz="0"/>
    </inertial>
  </link>

  <joint name="front_left_caster_joint" type = "continuous">
    <axis xyz="0 0 1"/>
    <parent link="base_link"/>
    <child link="front_left_caster"/>
    <origin rpy="0 0 0" xyz=".3 -.15 -.1"/>
    <dynamics damping="0.01" friction="100"/>
  </joint>

  <link name="back_left_caster">
    <visual>
      <geometry>
        <box size=".1 .1 .1"/>
      </geometry>
      <material name="silver"/>
    </visual>
    <collision>
      <geometry>
        <box size=".1 .1 .1"/>
      </geometry>
    </collision>
    <inertial>
      <mass value = ".10"/>
      <inertia ixx=".00083" iyy=".00083" izz=".00083" ixy="0" ixz="0" iyz="0"/>
    </inertial>
  </link>

  <joint name="back_left_caster_joint" type = "continuous">
    <axis xyz="0 0 1"/>
    <parent link="base_link"/>
    <child link="back_left_caster"/>
    <origin rpy="0 0 0" xyz="-.3 -.15 -.1"/>
    <dynamics damping="0.01" friction="100"/>
  </joint>

  <link name="back_right_caster">
    <visual>
      <geometry>
        <box size=".1 .1 .1"/>
      </geometry>
      <material name="silver"/>
    </visual>
    <collision>
      <geometry>
        <box size=".1 .1 .1"/>
      </geometry>
    </collision>
    <inertial>
      <mass value = ".10"/>
      <inertia ixx=".00083" iyy=".00083" izz=".00083" ixy="0" ixz="0" iyz="0"/>
    </inertial>
  </link>

  <joint name="back_right_caster_joint" type = "continuous">
    <axis xyz="0 0 1"/>
    <parent link="base_link"/>
    <child link="back_right_caster"/>
    <origin rpy="0 0 0" xyz="-.3 .15 -.1"/>
    <dynamics damping="0.01" friction="100"/>
  </joint>



  <link name="front_right_wheel">
    <visual>
      <geometry>
        <cylinder length=".05" radius=".035" />
      </geometry>
      <material name="black"/>
    </visual>
    <collision>
      <surface>
        <friction>
          <ode>
            <mu>1</mu>
            <mu2>1</mu2>
            <fdir1>0.000000 0.000000 0.000000</fdir1>
            <slip1>.5</slip1>
            <slip2>0</slip2>
          </ode>
        </friction>
      </surface>
      <geometry>
        <cylinder length=".05" radius=".035" />
      </geometry>
    </collision>
    <inertial>
      <mass value = ".10"/>
      <inertia ixx=".005" iyy=".005" izz=".01" ixy="0" ixz="0" iyz="0"/>
    </inertial>
  </link>

  <joint name="front_right_wheel_joint" type = "continuous">
    <axis xyz = "0 0 1"/>
    <parent link = "front_right_caster"/>
    <child link = "front_right_wheel"/>
    <origin rpy = "-1.5708 0 0" xyz="0.05 0 -.05"/>
  </joint>

  <link name="front_left_wheel">
    <visual>
      <geometry>
        <cylinder length=".05" radius=".035" />
      </geometry>
      <material name="black"/>
    </visual>
    <collision>
      <surface>
        <friction>
          <ode>
            <mu>1</mu>
            <mu2>1</mu2>
            <fdir1>0.000000 0.000000 0.000000</fdir1>
            <slip1>.5</slip1>
            <slip2>0</slip2>
          </ode>
        </friction>
      </surface>
      <geometry>
        <cylinder length=".05" radius=".035" />
      </geometry>
    </collision>
    <inertial>
      <mass value = ".10"/>
      <inertia ixx=".005" iyy=".005" izz=".01" ixy="0" ixz="0" iyz="0"/>
    </inertial>
  </link>

  <joint name="front_left_wheel_joint" type = "continuous">
    <axis xyz = "0 0 1"/>
    <parent link = "front_left_caster"/>
    <child link = "front_left_wheel"/>
    <origin rpy = "-1.5708 0 0" xyz="0.05 0 -.05"/>
  </joint>

  <link name="back_left_wheel">
    <visual>
      <geometry>
        <cylinder length=".05" radius=".035" />
      </geometry>
      <material name="black"/>
    </visual>
    <collision>
      <surface>
        <friction>
          <ode>
            <mu>1</mu>
            <mu2>1</mu2>
            <fdir1>0.000000 0.000000 0.000000</fdir1>
            <slip1>.5</slip1>
            <slip2>0</slip2>
          </ode>
        </friction>
      </surface>
      <geometry>
        <cylinder length=".05" radius=".035" />
      </geometry>
    </collision>
    <inertial>
      <mass value = ".10"/>
      <inertia ixx=".005" iyy=".005" izz=".01" ixy="0" ixz="0" iyz="0"/>
    </inertial>
  </link>

  <joint name="back_left_wheel_joint" type = "continuous">
    <axis xyz = "0 0 1"/>
    <parent link = "back_left_caster"/>
    <child link = "back_left_wheel"/>
    <origin rpy = "-1.5708 0 0" xyz="-0.05 0 -.05"/>
  </joint>


  <link name="back_right_wheel">
    <visual>
      <geometry>
        <cylinder length=".05" radius=".035" />
      </geometry>
      <material name="black"/>
    </visual>
    <collision>
      <surface>
        <friction>
          <ode>
            <mu>10</mu>
            <mu2>1</mu2>
            <fdir1>0.000000 0.000000 0.000000</fdir1>
            <slip1>.5</slip1>
            <slip2>0</slip2>
          </ode>
        </friction>
      </surface>
      <geometry>
        <cylinder length=".05" radius=".035" />
      </geometry>
    </collision>
    <inertial>
      <mass value = ".10"/>
      <inertia ixx=".005" iyy=".005" izz=".01" ixy="0" ixz="0" iyz="0"/>
    </inertial>
  </link>

  <joint name="back_right_wheel_joint" type = "continuous">
    <axis xyz = "0 0 1"/>
    <parent link = "back_right_caster"/>
    <child link = "back_right_wheel"/>
    <origin rpy = "-1.5708 0 0" xyz="-0.05 0 -.05"/>
  </joint>


  <link name="drive_right_wheel">
    <visual>
      <geometry>
        <cylinder length=".05" radius=".07" />
      </geometry>
      <material name="black"/>
    </visual>
    <collision>
      <surface>
        <friction>
          <ode>
            <mu>1</mu>
            <mu2>1</mu2>
            <fdir1>0.000000 0.000000 0.000000</fdir1>
            <slip1>.5</slip1>
            <slip2>0</slip2>
          </ode>
        </friction>
      </surface>
      <geometry>
        <cylinder length=".05" radius=".07" />
      </geometry>
    </collision>
    <inertial>
      <mass value = "1"/>
      <inertia ixx=".01" iyy=".01" izz=".02" ixy="0" ixz="0" iyz="0"/>
    </inertial>
  </link>

  <joint name="drive_right_wheel_joint" type = "continuous">
    <axis xyz = "0 0 1"/>
    <parent link = "base_link"/>
    <child link = "drive_right_wheel"/>
    <origin rpy = "-1.5708 0 0" xyz="0 -.15 -.115"/>
  </joint>

  <link name="drive_left_wheel">
    <visual>
      <geometry>
        <cylinder length=".05" radius=".07" />
      </geometry>
      <material name="black"/>
    </visual>
    <collision>
      <surface>
        <friction>
          <ode>
            <mu>1</mu>
            <mu2>1</mu2>
            <fdir1>0.000000 0.000000 0.000000</fdir1>
            <slip1>.5</slip1>
            <slip2>0</slip2>
          </ode>
        </friction>
      </surface>
      <geometry>
        <cylinder length=".05" radius=".07" />
      </geometry>
    </collision>
    <inertial>
      <mass value = "1.0"/>
      <inertia ixx=".01" iyy=".01" izz=".02" ixy="0" ixz="0" iyz="0"/>
    </inertial>
  </link>

  <joint name="drive_left_wheel_joint" type = "continuous">
    <axis xyz = "0 0 1"/>
    <parent link = "base_link"/>
    <child link = "drive_left_wheel"/>
    <origin rpy = "-1.5708 0 0" xyz="0 .15 -.115"/>
  </joint>

  <link name="hokuyo_link">
    <collision>
      <origin xyz = "0 0 0" rpy="0 0 0"/>
      <geometry>
        <box size=".05 .05 .05"/>
      </geometry>
    </collision>
    <visual>
      <material name="orange">
        <color rgba="255 50 0 1"/>
      </material>
      <origin xyz = "0 0 0" rpy="0 0 0"/>
      <geometry>
        <box size=".05 .05 .05"/>
      </geometry>
    </visual>
    <inertial>
      <mass value="1e-5"/>
      <origin xyz = "0 0 0" rpy="0 0 0"/>
      <inertia ixx="1e-6" iyy="1e-6" izz="1e-6" ixy="0" ixz="0" iyz="0"/>
    </inertial>
  </link>

  <joint name="hokuyo_joint" type="fixed">
    <axis xyz = "0 1 0" />
    <origin xyz = "0 0 0.125" rpy="0 0 0"/>
    <parent link="base_link"/>
    <child link="hokuyo_link"/>
  </joint>



  <gazebo>
    <plugin name="differential_drive_controller"
      filename="libgazebo_ros_diff_drive.so">
    <leftJoint>drive_right_wheel_joint</leftJoint>
    <rightJoint>drive_left_wheel_joint</rightJoint>
    <robotBaseFrame>base_link</robotBaseFrame>
    <wheelSeparation>0.35</wheelSeparation>
    <wheelDiameter>0.14</wheelDiameter>
    <publishWheelJointState>true</publishWheelJointState>
    <wheelTorque>20</wheelTorque>
    </plugin>

    <plugin name="joint_state publisher"
        filename="libgazebo_ros_joint_state_publisher.so">
      <jointName>front_left_caster_joint, front_left_wheel_joint,front_right_caster_joint, front_right_wheel_joint,back_left_caster_joint,  back_left_wheel_joint, back_right_caster_joint, back_right_wheel_joint
      </jointName>
    </plugin>

  </gazebo>

  <gazebo reference="hokuyo_link">
    <sensor type="gpu_ray" name="hokuyo">
      <pose>0 0 0 0 0 0</pose>
      <visualize>true</visualize>
      <update_rate>40</update_rate>
      <ray>
        <scan>
          <horizontal>
            <samples>720</samples>
            <resolution>.5</resolution>
            <min_angle>-3.14159</min_angle>
            <max_angle> 3.14159</max_angle>
          </horizontal>
        </scan>
        <range>
          <min>0.10</min>
          <max>30</max>
          <resolution>0.01</resolution>
        </range>
      </ray>
      <plugin name="gpu_laser" filename="libgazebo_ros_gpu_laser.so">
        <topicName>scan</topicName>
        <frameName>hokuyo_link</frameName>
      </plugin>
    </sensor>
  </gazebo>
  <gazebo>
    <plugin name="ground_truth" filename="libgazebo_ros_p3d.so">
      <frameName>map</frameName>
      <bodyName>base_link</bodyName>
      <topicName>ground_truth</topicName>
      <updateRate>40.0</updateRate>
    </plugin>
  </gazebo>
</robot>
